<?xml version="1.0" ?>
<!-- =================================================================================== -->
<!-- |    This document was autogenerated by xacro from beego.urdf                     | -->
<!-- |    EDITING THIS FILE BY HAND IS NOT RECOMMENDED                                 | -->
<!-- =================================================================================== -->
<robot name="beego">
  <material name="gray">
    <color rgba="0.75 0.75 0.75 1"/>
  </material>
  <!-- ===============  Body =============== -->
  <link name="base_link">
    <visual name="visual">
      <origin rpy="0 0 1.5707963" xyz="0 0 0"/>
      <geometry>
        <mesh filename="package://meshes/base_link.STL"/>
      </geometry>
      <material name="gray"/>
    </visual>
    <collision name="collision">
      <origin rpy="0 0 0" xyz="-0.05275 0 0.227"/>
      <geometry>
        <box size="0.25 0.3 0.004"/>
      </geometry>
    </collision>
    <inertial>
      <origin rpy="0 0 0" xyz="-0.05 0 0.1"/>
      <mass value="4.92"/>
      <inertia ixx="0.055432" ixy="0" ixz="0" iyy="0.064616" iyz="0" izz="0.064616"/>
    </inertial>
  </link>
  <link name="right_wheel_link">
    <visual>
      <origin rpy="0 0 0" xyz="0 0 0"/>
      <geometry>
        <mesh filename="package://meshes/right_wheel_link.STL"/>
      </geometry>
      <material name="gray"/>
    </visual>
    <collision>
      <origin rpy="0 0 0" xyz="0 0 -0.0083"/>
      <geometry>
        <cylinder length="0.015" radius="0.041"/>
      </geometry>
    </collision>
    <inertial>
      <origin rpy="0 0 0" xyz="0 0 -0.0083"/>
      <mass value="0.1"/>
      <inertia ixx="4.39e-05" ixy="0" ixz="0" iyy="4.39e-05" iyz="0" izz="8.405000000000001e-05"/>
    </inertial>
  </link>
  <joint name="right_wheel_joint" type="continuous">
    <origin rpy="-1.5707963 0 0" xyz="0.02225 -0.1308 -0.01"/>
    <parent link="base_link"/>
    <child link="right_wheel_link"/>
    <axis xyz="0 0 1"/>
    <!--<limit effort="1.07" velocity="3.14"/>
    <dynamics damping="0.1"/>-->
  </joint>
  <link name="left_wheel_link">
    <visual>
      <origin rpy="0 0 0" xyz="0 0 0"/>
      <geometry>
        <mesh filename="package://meshes/left_wheel_link.STL"/>
      </geometry>
      <material name="gray"/>
    </visual>
    <collision>
      <origin rpy="0 0 0" xyz="0 0 -0.0083"/>
      <geometry>
        <cylinder length="0.015" radius="0.041"/>
      </geometry>
    </collision>
    <inertial>
      <origin rpy="0 0 0" xyz="0 0 -0.0083"/>
      <mass value="0.1"/>
      <inertia ixx="4.39e-05" ixy="0" ixz="0" iyy="4.39e-05" iyz="0" izz="8.405000000000001e-05"/>
    </inertial>
  </link>
  <joint name="left_wheel_joint" type="continuous">
    <origin rpy="1.5707963 0 0" xyz="0.02225 0.1308 -0.01"/>
    <parent link="base_link"/>
    <child link="left_wheel_link"/>
    <axis xyz="0 0 -1"/>
    <!--<limit effort="1.07" velocity="3.14"/>
    <dynamics damping="0.1"/>-->
  </joint>
  <link name="caster_link">
    <collision>
      <origin rpy="0 0 0" xyz="0 0 0"/>
      <geometry>
        <sphere radius="0.041"/>
      </geometry>
    </collision>
  </link>
  <joint name="caster_joint" type="fixed">
    <origin rpy="0 0 0" xyz="-0.203 0 -0.01"/>
    <parent link="base_link"/>
    <child link="caster_link"/>
  </joint>
  <link name="base_footprint"/>
  <joint name="base_footprint_joint" type="fixed">
    <origin rpy="0 0 0" xyz="0 0 0.05"/>
    <parent link="base_footprint"/>
    <child link="base_link"/>
  </joint>
  <link name="hokuyo_link">
    <visual>
      <origin rpy="0 0 0" xyz="0 0 0"/>
      <geometry>
        <mesh filename="package://meshes/hokuyo.dae"/>
      </geometry>
    </visual>
    <collision>
      <origin rpy="0 0 0" xyz="0 0 0"/>
      <geometry>
        <box size="0.05 0.05 0.07"/>
      </geometry>
    </collision>
    <!--<inertial>
      <origin xyz="0 0 0" rpy="0 0 0"/>
      <mass value="0.16"/>
      <inertia ixx="${(1/12) * 0.16 * (0.05*0.05 + 0.07*0.07)}" ixy="0" ixz="0"
               iyy="${(1/12) * 0.16 * (0.05*0.05 + 0.07*0.07)}" iyz="0"
               izz="${(1/12) * 0.16 * (0.05*0.05 + 0.05*0.05)}"/>
    </inertial>-->
  </link>
  <joint name="hokuyo_joint" type="fixed">
    <origin rpy="0 0 0" xyz="0.012 0 0.185"/>
    <parent link="base_link"/>
    <child link="hokuyo_link"/>
    <axis xyz="0 1 0"/>
  </joint>
  <!-- ===============  Transmission =============== -->
  <transmission name="left_wheel_trans">
    <type>transmission_interface/SimpleTransmission</type>
    <joint name="left_wheel_joint">
      <hardwareInterface>hardware_interface/VelocityJointInterface</hardwareInterface>
    </joint>
    <actuator name="left_wheel_motor">
      <hardwareInterface>hardware_interface/VelocityJointInterface</hardwareInterface>
      <mechanicalReduction>30</mechanicalReduction>
    </actuator>
  </transmission>
  <transmission name="right_wheel_trans">
    <type>transmission_interface/SimpleTransmission</type>
    <joint name="right_wheel_joint">
      <hardwareInterface>hardware_interface/VelocityJointInterface</hardwareInterface>
    </joint>
    <actuator name="right_wheel_motor">
      <hardwareInterface>hardware_interface/VelocityJointInterface</hardwareInterface>
      <mechanicalReduction>30</mechanicalReduction>
    </actuator>
  </transmission>
  <!-- ===============  Sensor =============== -->
  <gazebo reference="hokuyo_link">
    <sensor name="head_hokuyo_sensor" type="ray">
      <pose>0 0 0 0 0 0</pose>
      <visualize>false</visualize>
      <update_rate>10</update_rate>
      <ray>
        <scan>
          <horizontal>
            <samples>726</samples>
            <resolution>1</resolution>
            <min_angle>-2.094395</min_angle>
            <max_angle>2.094395</max_angle>
          </horizontal>
        </scan>
        <range>
          <min>0.1</min>
          <max>5.6</max>
          <resolution>0.01</resolution>
        </range>
        <noise>
          <type>gaussian</type>
          <!-- Noise parameters based on published spec for Hokuyo laser
               achieving "+-30mm" accuracy at range < 10m.  A mean of 0.0m and
               stddev of 0.01m will put 99.7% of samples within 0.03m of the true
               reading. -->
          <mean>0.0</mean>
          <stddev>0.01</stddev>
        </noise>
      </ray>
      <plugin filename="libgazebo_ros_laser.so" name="gazebo_ros_head_hokuyo_controller">
        <topicName>scan</topicName>
        <frameName>hokuyo_link</frameName>
      </plugin>
    </sensor>
  </gazebo>
  <!-- =============== Gazebo =============== -->
  <gazebo>
    <plugin filename="libgazebo_ros_control.so" name="gazebo_ros_control">
      <!--<robotNamespace>beego</robotNamespace>-->
      <robotSimType>gazebo_ros_control/DefaultRobotHWSim</robotSimType>
      <legacyModeNS>true</legacyModeNS>
    </plugin>
  </gazebo>
  <gazebo reference="base_link">
    <selfCollide>true</selfCollide>
    <mu1 value="0.05"/>
    <mu2 value="0.05"/>
  </gazebo>
  <gazebo reference="left_wheel_link">
    <selfCollide>true</selfCollide>
    <mu1 value="1.0"/>
    <mu2 value="1.0"/>
    <!--<kp value="10000000.0"/>
    <kd value="1.0"/>-->
  </gazebo>
  <gazebo reference="right_wheel_link">
    <selfCollide>true</selfCollide>
    <mu1 value="1.0"/>
    <mu2 value="1.0"/>
    <!--<kp value="10000000.0"/>
    <kd value="1.0"/>-->
  </gazebo>
  <gazebo reference="caster_link">
    <selfCollide>true</selfCollide>
    <mu1 value="0.1"/>
    <mu2 value="0.1"/>
  </gazebo>
</robot>

